<mujoco model="aloha with cloth">
  <compiler autolimits="true" boundmass="0.01" boundinertia="9.9999999999999995e-07" angle="radian" meshdir="../aloha_pot"/>
  <option solver="CG" tolerance="1e-6" jacobian="sparse"/>
  <visual>
    <global azimuth="90" elevation="-20" offwidth="848" offheight="480"/>
    <quality shadowsize="8192"/>
    <headlight ambient="0.29999999999999999 0.29999999999999999 0.29999999999999999" diffuse="0.59999999999999998 0.59999999999999998 0.59999999999999998" specular="0 0 0"/>
    <rgba haze="0.14999999999999999 0.25 0.34999999999999998 1"/>
  </visual>
  <statistic meansize="0.050000000000000003" extent="0.59999999999999998" center="0 -0.10000000000000001 0.20000000000000001"/>
  <default>
    <default class="/">
      <default class="frame">
        <geom type="mesh" group="1" material="black"/>
      </default>
      <default class="vx300s">
        <joint axis="0 1 0" actuatorfrcrange="-35 35"/>
        <site group="4"/>
        <default class="waist">
          <joint axis="0 0 1" range="-3.1415799999999998 3.1415799999999998" damping="5.7599999999999998"/>
          <position ctrlrange="-3.1415799999999998 3.1415799999999998" kp="43"/>
        </default>
        <default class="shoulder">
          <joint range="-1.85005 1.25664" actuatorfrcrange="-144 144" armature="0.39500000000000002" damping="20" frictionloss="2"/>
          <position ctrlrange="-1.85005 1.25664" kp="265"/>
        </default>
        <default class="elbow">
          <joint range="-1.76278 1.6056999999999999" actuatorfrcrange="-59 59" armature="0.38300000000000001" damping="18.489999999999998" frictionloss="1.1499999999999999"/>
          <position ctrlrange="-1.76278 1.6056999999999999" kp="227"/>
        </default>
        <default class="forearm_roll">
          <joint axis="1 0 0" range="-3.1415799999999998 3.1415799999999998" actuatorfrcrange="-22 22" armature="0.14000000000000001" damping="6.7800000000000002"/>
          <position ctrlrange="-3.1415799999999998 3.1415799999999998" kp="78"/>
        </default>
        <default class="wrist_angle">
          <joint range="-1.8674999999999999 2.2340200000000001" armature="0.0080000000000000002" damping="6.2800000000000002"/>
          <position ctrlrange="-1.8674999999999999 2.2340200000000001" kp="37"/>
        </default>
        <default class="wrist_rotate">
          <joint axis="1 0 0" range="-3.1415799999999998 3.1415799999999998" damping="1.2"/>
          <position ctrlrange="-3.1415799999999998 3.1415799999999998" kp="10.4"/>
        </default>
        <default class="finger">
          <joint type="slide" armature="0.24299999999999999" damping="40"/>
          <position ctrlrange="0.002 0.036999999999999998" kp="2000" kv="124"/>
          <default class="left_finger">
            <joint axis="0 0 -1" range="0 0.041000000000000002"/>
          </default>
          <default class="right_finger">
            <joint axis="0 0 -1" range="0 0.041000000000000002"/>
          </default>
        </default>
        <default class="visual">
          <geom type="mesh" contype="0" conaffinity="0" group="2" material="black" density="0"/>
        </default>
        <default class="collision">
          <geom type="mesh" group="3"/>
          <default class="finger_collision">
            <geom condim="4" friction="1 0.0050000000000000001 0.0001" solref="0.01 1" solimp="2 1 0.01"/>
          </default>
          <default class="sphere_collision">
            <geom type="sphere" size="0.00059999999999999995" rgba="1 0 0 1"/>
          </default>
        </default>
      </default>
    </default>
    <default class="partnet_100015/">
      <joint frictionloss="1"/>
      <default class="partnet_100015/collision">
        <mesh scale="0.20000000000000001 0.20000000000000001 0.20000000000000001" inertia="convex"/>
        <geom type="mesh"/>
      </default>
    </default>
  </default>
  <asset>
    <mesh name="extrusion_2040_880" class="/" file="extrusion_2040_880-df10c72c0b4ae36b2e4f79e29fe1fe8f3a9a678a.stl"/>
    <mesh name="extrusion_150" class="/" file="extrusion_150-62e2ad6e912937b9c5f0ebde8e23f34ff982455a.stl"/>
    <mesh name="corner_bracket" class="/" file="corner_bracket-c4129cf77510d68c89cf2ddf67bd36dacef387b3.stl"/>
    <mesh name="extrusion_1220" class="/" file="extrusion_1220-a3c8ad369e839057b4e10539978b87e39b5f81bf.stl"/>
    <mesh name="extrusion_1000" class="/" file="extrusion_1000-421ca8ed83291edde7bc9ab61d7d4828b37b0343.stl"/>
    <mesh name="angled_extrusion" class="/" file="angled_extrusion-2b8426c7d466d59b03a7f048c5304d28205b3069.stl"/>
    <mesh name="extrusion_600" class="/" file="extrusion_600-87df49f763bf3784925b76eab16d8c28641a4529.stl"/>
    <mesh name="overhead_mount" class="/" file="overhead_mount-2edf90098757a980b68bc9b546bddce3257c7263.stl"/>
    <mesh name="extrusion_2040_1000" class="/" file="extrusion_2040_1000-3ae7ca5723c6e8bedf8a1138046f5419c7440b72.stl"/>
    <mesh name="wormseye_mount" class="/" file="wormseye_mount-4ac7acdce0b7e4d90ec0ec56b4fcd8a7ff0cf2e7.stl"/>
    <mesh name="tablelegs" class="/" file="tablelegs-d0aaf6399ee429de60273fe61f29a7a7fcd20440.obj"/>
    <mesh name="tabletop" class="/" file="tabletop-2972d9cc47a6f6792f1b4a7fd4ac6e6862d06105.obj"/>
    <mesh name="table_mesh_mapped" class="/" file="table_mesh_mapped-6c055adb309111efb32fb9fc0417883865cf9bf2.obj"/>
    <texture name="//unnamed_texture_3" type="skybox" builtin="gradient" rgb1="0.29999999999999999 0.5 0.69999999999999996" rgb2="0 0 0" width="512" height="3072"/>
    <texture name="groundplane" type="2d" builtin="checker" rgb1="0.20000000000000001 0.29999999999999999 0.40000000000000002" rgb2="0.10000000000000001 0.20000000000000001 0.29999999999999999" mark="edge" markrgb="0.80000000000000004 0.80000000000000004 0.80000000000000004" width="300" height="300"/>
    <material name="groundplane" class="/" texture="groundplane" texrepeat="5 5" texuniform="true" reflectance="0.20000000000000001"/>
    <material name="metal" class="/" rgba="0.51700000000000002 0.52900000000000003 0.53700000000000003 1"/>
    <material name="black" class="/" rgba="0.14999999999999999 0.14999999999999999 0.14999999999999999 1"/>
    <mesh name="vx300s_1_base" class="/" file="vx300s_1_base-8911efddeb54716caf91218e0beee848e0083aad.stl" scale="0.001 0.001 0.001"/>
    <mesh name="vx300s_2_shoulder" class="/" file="vx300s_2_shoulder-5dee3af162e071b59ae35b1b7279fe257c375ffb.stl" scale="0.001 0.001 0.001"/>
    <mesh name="vx300s_3_upper_arm" class="/" file="vx300s_3_upper_arm-f0b3692a22ad52ba9b3c439033c552c51222ed28.stl" scale="0.001 0.001 0.001"/>
    <mesh name="vx300s_4_upper_forearm" class="/" file="vx300s_4_upper_forearm-6d4b69653fd0cc02e83bb7d65ba3e7ec1604b71c.stl" scale="0.001 0.001 0.001"/>
    <mesh name="vx300s_5_lower_forearm" class="/" file="vx300s_5_lower_forearm-8555d345ad2564df22bcbd24557f5a69d362ef68.stl" scale="0.001 0.001 0.001"/>
    <mesh name="vx300s_6_wrist" class="/" file="vx300s_6_wrist-b3facdc0498ab0119fb164f573de994a27c7401e.stl" scale="0.001 0.001 0.001"/>
    <mesh name="vx300s_7_gripper_prop" class="/" file="vx300s_7_gripper_prop-fb8e61f159d0594d74deb8fabda682e9971dc2b5.stl"/>
    <mesh name="vx300s_7_gripper_bar" class="/" file="vx300s_7_gripper_bar-c5f4b35b626deb7894668277f953fc4143ad9898.stl"/>
    <mesh name="vx300s_7_gripper_wrist_mount" class="/" file="vx300s_7_gripper_wrist_mount-61d29471843d7ca6e0e8a970bdc9256a822c8b15.stl"/>
    <mesh name="vx300s_8_custom_finger_left" class="/" file="vx300s_8_custom_finger_left-bf982864f8591ef106a4b771fc7502c724ef3d7c.stl"/>
    <mesh name="vx300s_8_custom_finger_right" class="/" file="vx300s_8_custom_finger_right-41349941da5624f43b137273d462f62ab9605c36.stl"/>
    <mesh name="d405_solid" class="/" file="d405_solid-a35f08a7e5e7488eb120fc62c3e6458e6be0f956.stl"/>
  </asset>
  <worldbody>
    <light name="light" class="/" castshadow="true" pos="0 0.10000000000000001 2.5"/>
    <geom name="floor" class="/" type="plane" size="2 2 0.050000000000000003" material="groundplane" pos="0 0 -0.75"/>
    <body name="table" pos="0 0 -0.75">
      <site name="worldref" class="/"/>
      <geom name="tabletop" class="visual" quat="1 0 0 1" mesh="tabletop"/>
      <geom name="tablelegs" class="visual" quat="1 0 0 1" mesh="tablelegs"/>
      <geom name="table" class="collision" type="box" size="0.60999999999999999 0.37 0.10000000000000001" pos="0 0 0.65090000000000003"/>
    </body>
    <camera name="overhead_cam" class="/" mode="fixed" fovy="58" pos="0 -0.30379400000000001 1.0252399999999999" quat="0.97633199999999998 0.216277 0 0"/>
    <camera name="worms_eye_cam" class="/" mode="fixed" fovy="58" pos="0 -0.37716699999999997 0.031605500000000002" quat="0.67265900000000001 0.73995299999999997 0 0"/>
    <geom name="//unnamed_geom_4" class="frame" pos="0.44 -0.36099999999999999 1.03" quat="0 1 0 1" mesh="extrusion_2040_880"/>
    <geom name="//unnamed_geom_5" class="frame" pos="0.44 -0.371 0.60999999999999999" quat="1 0 -1 0" mesh="extrusion_150"/>
    <geom name="//unnamed_geom_6" class="frame" pos="0 -0.30379400000000001 1.0252399999999999" quat="0 0 0.97629600000000005 0.21643999999999999" mesh="d405_solid"/>
    <geom name="//unnamed_geom_7" class="frame" pos="0.44 -0.38300000000000001 1.04" quat="0 0 -1 1" mesh="corner_bracket"/>
    <geom name="//unnamed_geom_8" class="frame" pos="-0.60999999999999999 -0.39100000000000001 -0.01" quat="0 -1 0 1" mesh="extrusion_1220"/>
    <geom name="//unnamed_geom_9" class="frame" pos="-0.58999999999999997 -0.371 0.60999999999999999" quat="0 -1 0 1" mesh="extrusion_150"/>
    <geom name="//unnamed_geom_10" class="frame" pos="0.41999999999999998 -0.38300000000000001 0.62" quat="1 1 1 -1" mesh="corner_bracket"/>
    <geom name="//unnamed_geom_11" class="frame" pos="0 -0.37716699999999997 0.031605500000000002" quat="0 0 -0.67236700000000005 -0.74021800000000004" mesh="d405_solid"/>
    <geom name="//unnamed_geom_12" class="frame" pos="0.60999999999999999 -0.38300000000000001 0.62" quat="0 0 1 -1" mesh="corner_bracket"/>
    <geom name="//unnamed_geom_13" class="frame" pos="-0.42999999999999999 -0.36099999999999999 1.02" quat="0 0 0 1" mesh="extrusion_2040_1000"/>
    <geom name="//unnamed_geom_14" class="frame" pos="-0.60999999999999999 -0.38300000000000001 0.62" quat="1 1 1 -1" mesh="corner_bracket"/>
    <geom name="//unnamed_geom_15" class="frame" material="metal" pos="-0.42999999999999999 -0.23999999999999999 0.12" quat="0.92300000000000004 0.38200000000000001 0 0" mesh="angled_extrusion"/>
    <geom name="//unnamed_geom_16" class="frame" pos="-0.58999999999999997 -0.066000000000000003 0.01" quat="0 1 0 -1" mesh="extrusion_150"/>
    <geom name="//unnamed_geom_17" class="frame" pos="-0.59999999999999998 -0.371 0.62" quat="0 0 0 -1" mesh="extrusion_600"/>
    <geom name="//unnamed_geom_18" class="frame" pos="0.44 -0.63100000000000001 0.01" quat="1 0 -1 0" mesh="extrusion_150"/>
    <geom name="//unnamed_geom_19" class="frame" pos="0 -0.35099999999999998 1.03" quat="0 0 1 1" mesh="overhead_mount"/>
    <geom name="//unnamed_geom_20" class="frame" pos="-0.42999999999999999 -0.64100000000000001 0.01" quat="1 1 -1 1" mesh="extrusion_1000"/>
    <geom name="//unnamed_geom_21" class="frame" material="metal" pos="0.59999999999999998 -0.26000000000000001 0.12" quat="0.92300000000000004 0.38200000000000001 0 0" mesh="angled_extrusion"/>
    <geom name="//unnamed_geom_22" class="frame" pos="0.44 -0.066000000000000003 0.01" quat="1 0 -1 0" mesh="extrusion_150"/>
    <geom name="//unnamed_geom_23" class="frame" pos="-0.44 -0.38300000000000001 1.04" quat="1 1 1 -1" mesh="corner_bracket"/>
    <geom name="//unnamed_geom_24" class="frame" pos="-0.60999999999999999 0.36899999999999999 0.01" quat="0 1 0 -1" mesh="extrusion_1220"/>
    <geom name="//unnamed_geom_25" class="frame" pos="0.42999999999999999 -0.64100000000000001 0.01" quat="0 0 -1 1" mesh="extrusion_1000"/>
    <geom name="//unnamed_geom_26" class="frame" pos="0.59999999999999998 -0.64100000000000001 0.01" quat="0 0 -1 1" mesh="extrusion_1000"/>
    <geom name="//unnamed_geom_27" class="frame" pos="-0.58999999999999997 -0.63100000000000001 0.01" quat="0 1 0 -1" mesh="extrusion_150"/>
    <geom name="//unnamed_geom_28" class="frame" pos="-0.41999999999999998 -0.38300000000000001 0.62" quat="0 0 -1 1" mesh="corner_bracket"/>
    <geom name="//unnamed_geom_29" class="frame" pos="-0.59999999999999998 -0.64100000000000001 0.01" quat="0 0 -1 1" mesh="extrusion_1000"/>
    <geom name="//unnamed_geom_30" class="frame" pos="0.59999999999999998 -0.371 0.62" quat="1 0 0 1" mesh="extrusion_600"/>
    <geom name="//unnamed_geom_31" class="frame" material="metal" pos="0.42999999999999999 -0.23999999999999999 0.12" quat="0.92300000000000004 0.38200000000000001 0 0" mesh="angled_extrusion"/>
    <geom name="//unnamed_geom_32" class="frame" material="metal" pos="-0.59999999999999998 -0.26000000000000001 0.12" quat="0.92300000000000004 0.38200000000000001 0 0" mesh="angled_extrusion"/>
    <geom name="//unnamed_geom_33" class="frame" pos="0.42999999999999999 -0.36099999999999999 1.02" quat="0 0 0 1" mesh="extrusion_2040_1000"/>
    <geom name="//unnamed_geom_34" class="frame" pos="0 -0.39100000000000001 -0.01" quat="0 0 0 1" mesh="wormseye_mount"/>
    <light name="tracking_light_left" class="/" mode="targetbodycom" target="left\gripper_link" pos="-0.5 0.69999999999999996 2.5" cutoff="55"/>
    <light name="tracking_light_right" class="/" mode="targetbodycom" target="right\gripper_link" pos="0.5 0.69999999999999996 2.5" cutoff="55"/>
    <camera name="teleoperator_pov" class="/" pos="0 -1.3540000000000001 0.68500000000000005" xyaxes="1 0 0 0 0.20000000000000001 0.80000000000000004"/>
    <camera name="collaborator_pov" class="/" pos="0 1.5 0.80000000000000004" xyaxes="-1 0 0 0 -0.20000000000000001 0.80000000000000004"/>
    <body name="left\base_link" childclass="vx300s" pos="-0.46899999999999997 -0.019 0.02">
      <site name="left\base" group="5" pos="0 0 0"/>
      <inertial pos="-0.053477400000000001 -0.00056257500000000005 0.020596099999999999" quat="-0.0029232400000000001 0.71251699999999996 0.00480387 0.70163299999999995" mass="0.96903399999999995" diaginertia="0.0071633 0.0060245100000000003 0.00169819"/>
      <geom name="//unnamed_geom_35" class="visual" quat="1 0 0 1" mesh="vx300s_1_base"/>
      <geom name="//unnamed_geom_36" class="collision" quat="1 0 0 1" mesh="vx300s_1_base"/>
      <body name="left\shoulder_link" pos="0 0 0.079000000000000001">
        <inertial pos="0.00025923299999999999 -3.3552000000000001e-06 0.011612900000000001" quat="-0.47611900000000001 0.47608299999999998 0.52278999999999998 0.52282600000000001" mass="0.79861400000000005" diaginertia="0.00120156 0.00113744 0.00093880000000000005"/>
        <joint name="left\waist" class="waist"/>
        <site name="left\waist" group="5" pos="0 0 0"/>
        <geom name="//unnamed_geom_37" class="visual" pos="0 0 -0.0030000000000000001" quat="1 0 0 1" mesh="vx300s_2_shoulder"/>
        <geom name="//unnamed_geom_38" class="collision" pos="0 0 -0.0030000000000000001" quat="1 0 0 1" mesh="vx300s_2_shoulder"/>
        <body name="left\upper_arm_link" pos="0 0 0.048050000000000002">
          <inertial pos="0.020694899999999999 4.0000000000000001e-10 0.22645899999999999" quat="0 0.072845800000000002 0 0.99734299999999998" mass="0.79259199999999996" diaginertia="0.0091133800000000008 0.0089250000000000006 0.00075931700000000002"/>
          <joint name="left\shoulder" class="shoulder"/>
          <site name="left\shoulder" group="5" pos="0 0 0"/>
          <geom name="//unnamed_geom_39" class="visual" quat="1 0 0 1" mesh="vx300s_3_upper_arm"/>
          <geom name="//unnamed_geom_40" class="collision" quat="1 0 0 1" mesh="vx300s_3_upper_arm"/>
          <body name="left\upper_forearm_link" pos="0.059549999999999999 0 0.29999999999999999">
            <inertial pos="0.105723 0 0" quat="-0.00062163099999999998 0.70472400000000002 0.010529200000000001 0.70940300000000001" mass="0.32222800000000001" diaginertia="0.00144107 0.0013422799999999999 0.00015204699999999999"/>
            <site name="left\elbow" group="5" pos="0 0 0"/>
            <joint name="left\elbow" class="elbow"/>
            <geom name="//unnamed_geom_41" class="visual" mesh="vx300s_4_upper_forearm"/>
            <geom name="//unnamed_geom_42" class="collision" mesh="vx300s_4_upper_forearm"/>
            <body name="left\lower_forearm_link" pos="0.20000000000000001 0 0">
              <inertial pos="0.051347700000000003 0.0068046199999999999 0" quat="-0.70260400000000001 -0.079672400000000004 -0.70260400000000001 0.079672400000000004" mass="0.414823" diaginertia="0.0005911 0.000546493 0.00015570699999999999"/>
              <joint name="left\forearm_roll" class="forearm_roll"/>
              <geom name="//unnamed_geom_43" class="visual" quat="0 1 0 0" mesh="vx300s_5_lower_forearm"/>
              <geom name="//unnamed_geom_44" class="collision" quat="0 1 0 0" mesh="vx300s_5_lower_forearm"/>
              <body name="left\wrist_link" pos="0.10000000000000001 0 0">
                <site name="left\wrist" group="5" pos="0 0 0"/>
                <inertial pos="0.046743 -7.6652000000000007e-06 0.010565" quat="-0.00100191 0.54458600000000001 0.0026583000000000002 0.8387" mass="0.115395" diaginertia="5.4570700000000003e-05 4.6310100000000002e-05 4.3269200000000002e-05"/>
                <joint name="left\wrist_angle" class="wrist_angle"/>
                <geom name="//unnamed_geom_45" class="visual" quat="1 0 0 1" mesh="vx300s_6_wrist"/>
                <geom name="//unnamed_geom_46" class="collision" quat="1 0 0 1" mesh="vx300s_6_wrist"/>
                <body name="left\gripper_link" pos="0.069744 0 0">
                  <inertial pos="0.039566200000000003 -2.5631100000000002e-07 0.0040064899999999997" quat="0.62033000000000005 0.61991600000000002 -0.33968199999999998 0.33986899999999998" mass="0.25165199999999999" diaginertia="0.00068954599999999997 0.00065031599999999996 0.000468142"/>
                  <joint name="left\wrist_rotate" class="wrist_rotate"/>
                  <site name="left\gripper" group="5" pos="0.14999999999999999 0 0"/>
                  <body name="left\gripper_base" pos="0.035000000000000003 0 0" euler="0 1.5700000000000001 -1.5700000000000001">
                    <inertial pos="0.00018215399999999999 -0.034158899999999999 -0.0106026" quat="0.43528600000000001 0.55707399999999996 -0.551539 0.442718" mass="0.42158000000000001" diaginertia="0.0011043800000000001 0.00079053700000000001 0.00046972700000000002"/>
                    <geom name="//unnamed_geom_47" class="visual" mesh="vx300s_7_gripper_prop"/>
                    <geom name="//unnamed_geom_48" class="collision" mesh="vx300s_7_gripper_prop"/>
                    <geom name="//unnamed_geom_49" class="visual" mesh="vx300s_7_gripper_bar"/>
                    <geom name="//unnamed_geom_50" class="collision" mesh="vx300s_7_gripper_bar"/>
                    <geom name="//unnamed_geom_51" class="visual" type="mesh" pos="0 -0.035249999999999997 -0.022700000000000001" quat="0 -1 0 -1" mesh="vx300s_7_gripper_wrist_mount"/>
                    <geom name="//unnamed_geom_52" class="collision" type="mesh" pos="0 -0.035249999999999997 -0.022700000000000001" quat="0 -1 0 -1" mesh="vx300s_7_gripper_wrist_mount"/>
                    <geom name="//unnamed_geom_53" class="visual" type="mesh" pos="0 -0.082474800000000001 -0.0095954999999999999" quat="0 0 -0.21643999999999999 -0.97629600000000005" mesh="d405_solid"/>
                    <geom name="//unnamed_geom_54" class="collision" type="mesh" pos="0 -0.082474800000000001 -0.0095954999999999999" quat="0 0 -0.21643999999999999 -0.97629600000000005" mesh="d405_solid"/>
                    <camera name="wrist_cam_left" mode="fixed" fovy="58" pos="0 -0.082474800000000001 -0.0095954999999999999" euler="2.7052595535899999 0 0"/>
                    <body name="left\left_finger_link" pos="0.019099999999999999 -0.0141637 0.021172699999999999" quat="1 -1 -1 1">
                      <inertial pos="0.014347800000000001 -0.0284791 0.012289700000000001" quat="0.53548600000000002 0.45876600000000001 -0.450407 0.547651" mass="0.086293700000000001" diaginertia="5.8684799999999998e-05 4.4688699999999998e-05 1.8397e-05"/>
                      <joint name="left\left_finger" class="left_finger"/>
                      <geom name="//unnamed_geom_55" class="visual" type="mesh" pos="0.0141637 0.021172699999999999 0.059999999999999998" quat="1 1 1 -1" mesh="vx300s_8_custom_finger_left"/>
                      <geom name="//unnamed_geom_56" class="finger_collision" type="mesh" pos="0.0141637 0.021172699999999999 0.059999999999999998" quat="1 1 1 -1" mesh="vx300s_8_custom_finger_left"/>
                      <geom name="//unnamed_geom_57" class="sphere_collision" pos="0.012999999999999999 -0.089200000000000002 0.026800000000000001"/>
                      <geom name="//unnamed_geom_58" class="sphere_collision" pos="0.022200000000000001 -0.089200000000000002 0.026800000000000001"/>
                      <geom name="//unnamed_geom_59" class="sphere_collision" pos="0.018200000000000001 -0.084500000000000006 0.026599999999999999"/>
                      <site name="left\left_finger" pos="0.014999999999999999 -0.059999999999999998 0.02"/>
                    </body>
                    <body name="left\right_finger_link" pos="-0.019099999999999999 -0.0141637 0.021172699999999999" quat="1 1 1 1">
                      <inertial pos="0.014371099999999999 0.0284792 0.012142099999999999" quat="0.46131699999999998 0.53761499999999995 -0.54547800000000002 0.44789400000000001" mass="0.0862932" diaginertia="5.86828e-05 4.4688699999999998e-05 1.8394899999999999e-05"/>
                      <joint name="left\right_finger" class="right_finger"/>
                      <geom name="//unnamed_geom_60" class="visual" type="mesh" pos="0.0141637 -0.021172699999999999 0.059706700000000001" quat="1 -1 -1 -1" mesh="vx300s_8_custom_finger_right"/>
                      <geom name="//unnamed_geom_61" class="finger_collision" type="mesh" pos="0.0141637 -0.021172699999999999 0.059706700000000001" quat="1 -1 -1 -1" mesh="vx300s_8_custom_finger_right"/>
                      <geom name="//unnamed_geom_62" class="sphere_collision" pos="0.012999999999999999 0.089200000000000002 0.026800000000000001"/>
                      <geom name="//unnamed_geom_63" class="sphere_collision" pos="0.022200000000000001 0.089200000000000002 0.026800000000000001"/>
                      <geom name="//unnamed_geom_64" class="sphere_collision" pos="0.018200000000000001 0.084500000000000006 0.026599999999999999"/>
                      <site name="left\right_finger" pos="0.014999999999999999 0.059999999999999998 0.02"/>
                    </body>
                  </body>
                </body>
              </body>
            </body>
          </body>
        </body>
      </body>
    </body>
    <body name="right\base_link" childclass="vx300s" pos="0.46899999999999997 -0.019 0.02" quat="0 0 0 1">
      <site name="right\base" group="5" pos="0 0 0"/>
      <inertial pos="-0.053477400000000001 -0.00056257500000000005 0.020596099999999999" quat="-0.0029232400000000001 0.71251699999999996 0.00480387 0.70163299999999995" mass="0.96903399999999995" diaginertia="0.0071633 0.0060245100000000003 0.00169819"/>
      <geom name="//unnamed_geom_65" class="visual" quat="1 0 0 1" mesh="vx300s_1_base"/>
      <geom name="//unnamed_geom_66" class="collision" quat="1 0 0 1" mesh="vx300s_1_base"/>
      <body name="right\shoulder_link" pos="0 0 0.079000000000000001">
        <inertial pos="0.00025923299999999999 -3.3552000000000001e-06 0.011612900000000001" quat="-0.47611900000000001 0.47608299999999998 0.52278999999999998 0.52282600000000001" mass="0.79861400000000005" diaginertia="0.00120156 0.00113744 0.00093880000000000005"/>
        <joint name="right\waist" class="waist"/>
        <site name="right\waist" group="5" pos="0 0 0"/>
        <geom name="//unnamed_geom_67" class="visual" pos="0 0 -0.0030000000000000001" quat="1 0 0 1" mesh="vx300s_2_shoulder"/>
        <geom name="//unnamed_geom_68" class="collision" pos="0 0 -0.0030000000000000001" quat="1 0 0 1" mesh="vx300s_2_shoulder"/>
        <body name="right\upper_arm_link" pos="0 0 0.048050000000000002">
          <inertial pos="0.020694899999999999 4.0000000000000001e-10 0.22645899999999999" quat="0 0.072845800000000002 0 0.99734299999999998" mass="0.79259199999999996" diaginertia="0.0091133800000000008 0.0089250000000000006 0.00075931700000000002"/>
          <joint name="right\shoulder" class="shoulder"/>
          <site name="right\shoulder" group="5" pos="0 0 0"/>
          <geom name="//unnamed_geom_69" class="visual" quat="1 0 0 1" mesh="vx300s_3_upper_arm"/>
          <geom name="//unnamed_geom_70" class="collision" quat="1 0 0 1" mesh="vx300s_3_upper_arm"/>
          <body name="right\upper_forearm_link" pos="0.059549999999999999 0 0.29999999999999999">
            <inertial pos="0.105723 0 0" quat="-0.00062163099999999998 0.70472400000000002 0.010529200000000001 0.70940300000000001" mass="0.32222800000000001" diaginertia="0.00144107 0.0013422799999999999 0.00015204699999999999"/>
            <joint name="right\elbow" class="elbow"/>
            <site name="right\elbow" group="5" pos="0 0 0"/>
            <geom name="//unnamed_geom_71" class="visual" mesh="vx300s_4_upper_forearm"/>
            <geom name="//unnamed_geom_72" class="collision" mesh="vx300s_4_upper_forearm"/>
            <body name="right\lower_forearm_link" pos="0.20000000000000001 0 0">
              <inertial pos="0.051347700000000003 0.0068046199999999999 0" quat="-0.70260400000000001 -0.079672400000000004 -0.70260400000000001 0.079672400000000004" mass="0.414823" diaginertia="0.0005911 0.000546493 0.00015570699999999999"/>
              <joint name="right\forearm_roll" class="forearm_roll"/>
              <geom name="//unnamed_geom_73" class="visual" quat="0 1 0 0" mesh="vx300s_5_lower_forearm"/>
              <geom name="//unnamed_geom_74" class="collision" quat="0 1 0 0" mesh="vx300s_5_lower_forearm"/>
              <body name="right\wrist_link" pos="0.10000000000000001 0 0">
                <site name="right\wrist" group="5" pos="0 0 0"/>
                <inertial pos="0.046743 -7.6652000000000007e-06 0.010565" quat="-0.00100191 0.54458600000000001 0.0026583000000000002 0.8387" mass="0.115395" diaginertia="5.4570700000000003e-05 4.6310100000000002e-05 4.3269200000000002e-05"/>
                <joint name="right\wrist_angle" class="wrist_angle"/>
                <geom name="//unnamed_geom_75" class="visual" quat="1 0 0 1" mesh="vx300s_6_wrist"/>
                <geom name="//unnamed_geom_76" class="collision" quat="1 0 0 1" mesh="vx300s_6_wrist"/>
                <body name="right\gripper_link" pos="0.069744 0 0">
                  <inertial pos="0.039566200000000003 -2.5631100000000002e-07 0.0040064899999999997" quat="0.62033000000000005 0.61991600000000002 -0.33968199999999998 0.33986899999999998" mass="0.25165199999999999" diaginertia="0.00068954599999999997 0.00065031599999999996 0.000468142"/>
                  <joint name="right\wrist_rotate" class="wrist_rotate"/>
                  <site name="right\gripper" group="5" pos="0.14999999999999999 0 0"/>
                  <body name="right\gripper_base" pos="0.035000000000000003 0 0" euler="0 1.5700000000000001 -1.5700000000000001">
                    <inertial pos="0.00018215399999999999 -0.034158899999999999 -0.0106026" quat="0.43528600000000001 0.55707399999999996 -0.551539 0.442718" mass="0.42158000000000001" diaginertia="0.0011043800000000001 0.00079053700000000001 0.00046972700000000002"/>
                    <geom name="//unnamed_geom_77" class="visual" mesh="vx300s_7_gripper_prop"/>
                    <geom name="//unnamed_geom_78" class="collision" mesh="vx300s_7_gripper_prop"/>
                    <geom name="//unnamed_geom_79" class="visual" mesh="vx300s_7_gripper_bar"/>
                    <geom name="//unnamed_geom_80" class="collision" mesh="vx300s_7_gripper_bar"/>
                    <geom name="//unnamed_geom_81" class="visual" type="mesh" pos="0 -0.035249999999999997 -0.022700000000000001" quat="0 -0.70710700000000004 0 -0.70710700000000004" mesh="vx300s_7_gripper_wrist_mount"/>
                    <geom name="//unnamed_geom_82" class="collision" type="mesh" pos="0 -0.035249999999999997 -0.022700000000000001" quat="0 -0.70710700000000004 0 -0.70710700000000004" mesh="vx300s_7_gripper_wrist_mount"/>
                    <geom name="//unnamed_geom_83" class="visual" type="mesh" pos="0 -0.082474800000000001 -0.0095954999999999999" quat="0 0 -0.21643999999999999 -0.97629600000000005" mesh="d405_solid"/>
                    <geom name="//unnamed_geom_84" class="collision" type="mesh" pos="0 -0.082474800000000001 -0.0095954999999999999" quat="0 0 -0.21643999999999999 -0.97629600000000005" mesh="d405_solid"/>
                    <camera name="wrist_cam_right" mode="fixed" fovy="58" pos="0 -0.082474800000000001 -0.0095954999999999999" euler="2.7052595535899999 0 0"/>
                    <body name="right\left_finger_link" pos="0.019099999999999999 -0.0141637 0.021172699999999999" quat="1 -1 -1 1">
                      <inertial pos="0.014347800000000001 -0.0284791 0.012289700000000001" quat="0.53548600000000002 0.45876600000000001 -0.450407 0.547651" mass="0.086293700000000001" diaginertia="5.8684799999999998e-05 4.4688699999999998e-05 1.8397e-05"/>
                      <joint name="right\left_finger" class="left_finger"/>
                      <geom name="//unnamed_geom_85" class="visual" type="mesh" pos="0.0141637 0.021172699999999999 0.059999999999999998" quat="1 1 1 -1" mesh="vx300s_8_custom_finger_left"/>
                      <geom name="//unnamed_geom_86" class="finger_collision" type="mesh" pos="0.0141637 0.021172699999999999 0.059999999999999998" quat="1 1 1 -1" mesh="vx300s_8_custom_finger_left"/>
                      <geom name="//unnamed_geom_87" class="sphere_collision" pos="0.012999999999999999 -0.089200000000000002 0.026800000000000001"/>
                      <geom name="//unnamed_geom_88" class="sphere_collision" pos="0.022200000000000001 -0.089200000000000002 0.026800000000000001"/>
                      <geom name="//unnamed_geom_89" class="sphere_collision" pos="0.018200000000000001 -0.084500000000000006 0.026599999999999999"/>
                      <site name="right\left_finger" pos="0.014999999999999999 -0.059999999999999998 0.02"/>
                    </body>
                    <body name="right\right_finger_link" pos="-0.019099999999999999 -0.0141637 0.021172699999999999" quat="1 1 1 1">
                      <inertial pos="0.014371099999999999 0.0284792 0.012142099999999999" quat="0.46131699999999998 0.53761499999999995 -0.54547800000000002 0.44789400000000001" mass="0.0862932" diaginertia="5.86828e-05 4.4688699999999998e-05 1.8394899999999999e-05"/>
                      <joint name="right\right_finger" class="right_finger"/>
                      <geom name="//unnamed_geom_90" class="visual" type="mesh" pos="0.0141637 -0.021172699999999999 0.059706700000000001" quat="1 -1 -1 -1" mesh="vx300s_8_custom_finger_right"/>
                      <geom name="//unnamed_geom_91" class="finger_collision" type="mesh" pos="0.0141637 -0.021172699999999999 0.059706700000000001" quat="1 -1 -1 -1" mesh="vx300s_8_custom_finger_right"/>
                      <geom name="//unnamed_geom_92" class="sphere_collision" pos="0.012999999999999999 0.089200000000000002 0.026800000000000001"/>
                      <geom name="//unnamed_geom_93" class="sphere_collision" pos="0.022200000000000001 0.089200000000000002 0.026800000000000001"/>
                      <geom name="//unnamed_geom_94" class="sphere_collision" pos="0.018200000000000001 0.084500000000000006 0.026599999999999999"/>
                      <site name="right\right_finger" pos="0.014999999999999999 0.059999999999999998 0.02"/>
                    </body>
                  </body>
                </body>
              </body>
            </body>
          </body>
        </body>
      </body>
    </body>
    <flexcomp name="towel" type="grid" count="30 30 1" spacing="0.014 0.014 0.014"
              radius="0.006" dim="2" rgba="1 0.5 0.5 1" pos="0 0 0" mass=".1">
      <edge equality="true"/>
      <elasticity young="3e3" poisson="0" thickness="1e-2" damping="1e-3" elastic2d="bend"/>
      <contact vertcollide="true" conaffinity="0" contype="0"/>
    </flexcomp>
  </worldbody>
  <contact>
    <exclude name="//unnamed_contact_0" body1="left\base_link" body2="left\shoulder_link"/>
    <exclude name="//unnamed_contact_1" body1="right\base_link" body2="right\shoulder_link"/>
  </contact>
  <equality>
    <joint name="//unnamed_equality_0" class="/" joint1="left\left_finger" joint2="left\right_finger" polycoef="0 1 0 0 0"/>
    <joint name="//unnamed_equality_1" class="/" joint1="right\left_finger" joint2="right\right_finger" polycoef="0 1 0 0 0"/>
  </equality>
  <actuator>
    <position name="left\waist" class="waist" joint="left\waist"/>
    <position name="left\shoulder" class="shoulder" joint="left\shoulder"/>
    <position name="left\elbow" class="elbow" joint="left\elbow"/>
    <position name="left\forearm_roll" class="forearm_roll" joint="left\forearm_roll"/>
    <position name="left\wrist_angle" class="wrist_angle" joint="left\wrist_angle"/>
    <position name="left\wrist_rotate" class="wrist_rotate" joint="left\wrist_rotate"/>
    <position name="left\gripper" class="finger" joint="left\left_finger"/>
    <position name="right\waist" class="waist" joint="right\waist"/>
    <position name="right\shoulder" class="shoulder" joint="right\shoulder"/>
    <position name="right\elbow" class="elbow" joint="right\elbow"/>
    <position name="right\forearm_roll" class="forearm_roll" joint="right\forearm_roll"/>
    <position name="right\wrist_angle" class="wrist_angle" joint="right\wrist_angle"/>
    <position name="right\wrist_rotate" class="wrist_rotate" joint="right\wrist_rotate"/>
    <position name="right\gripper" class="finger" joint="right\left_finger"/>
  </actuator>
  <keyframe>
    <key
      name="neutral_pose" 
      qpos="0 -0.95999999999999996 1.1599999999999999 0 -0.29999999999999999 0 0.0083999999999999995 0.0083999999999999995 0 -0.95999999999999996 1.1599999999999999 0 -0.29999999999999999 0 0.0083999999999999995 0.0083999999999999995" 
      ctrl="0 -0.95999999999999996 1.1599999999999999 0 -0.29999999999999999 0 0.0083999999999999995 0 -0.95999999999999996 1.1599999999999999 0 -0.29999999999999999 0 0.0083999999999999995"
    />
  </keyframe>
</mujoco>
